<?xml version="1.0"?>

<robot xmlns:xacro="http://www.ros.org/wiki/xacro"
 	xmlns:sensor="http://playerstage.sourceforge.net/gazebo/xmlschema/#sensor"
    	xmlns:controller="http://playerstage.sourceforge.net/gazebo/xmlschema/#controller"
    	xmlns:interface="http://playerstage.sourceforge.net/gazebo/xmlschema/#interface"
	name="robot1_xacro">


	<xacro:property name="length_wheel" value="0.05" />
	<xacro:property name="radius_wheel" value="0.05" />
	<xacro:property name="camera_link" value="0.05" />
  <xacro:property name="M_PI" value="3.1415926535897931" />
	<xacro:macro name="default_inertial" params="mass">
               <inertial>
                       <mass value="${mass}" />
                       <inertia ixx="1.0" ixy="0.0" ixz="0.0"
                                iyy="1.0" iyz="0.0"
                                izz="1.0" />
               </inertial>
	</xacro:macro>
  <xacro:include filename="saturn_property.urdf.xacro" />
	<link name="base_footprint">
   		<visual>
			<geometry>
      				<box size="0.001 0.001 0.001"/>
     			</geometry>
			<origin rpy="0 0 0" xyz="0 0 0"/>
   		</visual>
		<!--<xacro:default_inertial mass="0.0001"/>-->
 	</link>
 	<xacro:include filename="robot1.gazebo" />

	<gazebo reference="base_footprint">
		<material>Gazebo/Green</material>
		<turnGravityOff>false</turnGravityOff>
	</gazebo>

	<joint name="base_footprint_joint" type="fixed">
		<origin xyz="0 0 0" />
		<parent link="base_footprint" />
		<child link="base_link" />
	</joint>


	<link name="base_link">
   		<visual>
			<geometry>
      				<box size="0.2 .3 .1"/>
     			</geometry>
			<origin rpy="0 0 1.54" xyz="0 0 0.05"/>
			<material name="white">
				<color rgba="1 1 1 1"/>
			</material>
   		</visual>
		<collision>
			<geometry>
       				<box size="0.2 .3 0.1"/>
			</geometry>
		</collision>
		<xacro:default_inertial mass="10"/>
 	</link>

 	<link name="wheel_left">
   		<visual>
     			<geometry>
       				<cylinder length="${length_wheel}" radius="${radius_wheel}"/>
     			</geometry>
			<!-- <origin rpy="0 1.5 0" xyz="0.1 0.1 0"/> -->
			<origin rpy="0 0 0" xyz="0 0 0"/>
   			<material name="black">
				<color rgba="0 0 0 1"/>
			</material>
		</visual>
		<collision>
			<geometry>
       				<cylinder length="${length_wheel}" radius="${radius_wheel}"/>
			</geometry>
		</collision>
		<xacro:default_inertial mass="1"/>
 	</link>

 	<link name="wheel_right">
   		<visual>
     			<geometry>
       				<cylinder length="${length_wheel}" radius="${radius_wheel}"/>
     			</geometry>
			<!-- <origin rpy="0 1.5 0" xyz="-0.1 0.1 0"/> -->
			<origin rpy="0 0 0" xyz="0 0 0"/>
   			<material name="black"/>
   		</visual>
		<collision>
			<geometry>
       				<cylinder length="${length_wheel}" radius="${radius_wheel}"/>
			</geometry>
		</collision>
		<xacro:default_inertial mass="1"/>

 	</link>

 	<link name="caster_wheel">
   		<visual>
     			<geometry>
       				<sphere radius="${radius_wheel}"/>
     			</geometry>
			<!-- <origin rpy="0 1.5 0" xyz="0.1 -0.1 0"/> -->

			<origin rpy="0 0 0" xyz="0 0 0"/>
   			<material name="black"/>
   		</visual>
		<collision>
			<geometry>
       				<sphere radius="${radius_wheel}"/>
			</geometry>
		</collision>
		<xacro:default_inertial mass="1"/>
 	</link>

 <joint name="base_to_wheel_left" type="continuous">
   <parent link="base_link"/>
   <child link="wheel_left"/>
   <origin rpy="-1.5707 0 0" xyz="-0.1 0.15 0"/>
   <axis xyz="0 0 1" />
 </joint>

 <joint name="base_to_wheel_right" type="continuous">
   <axis xyz="0 0 1" />
   <anchor xyz="0 0 0" />
   <limit effort="100" velocity="100" />
   <parent link="base_link"/>
   <child link="wheel_right"/>
   <origin rpy="-1.5707 0 0" xyz="-0.1 -0.15 0"/>
</joint>

 <joint name="base_to_caster_wheel" type="continuous">
   <parent link="base_link"/>
   <axis xyz="0 0 1" />
   <child link="caster_wheel"/>
   <origin rpy="-1.5707 0 0" xyz="0.1 0 0"/>
 </joint>

  <!-- Camera joint
  <joint name="camera_joint" type="fixed">
    <axis xyz="0 1 0" />
    <origin xyz="-0.1 0 0.25" rpy="0 0 0"/>
    <parent link="base_link"/>
    <child link="camera_link"/>
  </joint>-->

  <!-- Camera -->
  <xacro:property name="astra_cam_py" value="-0.0125"/>
  <!-- Parameterised in part by the values in saturn_properties.urdf.xacro -->
  <xacro:macro name="sensor_kinect" params="parent" />
  <xacro:property name="astra_depth_rel_rgb_py" value="0.0250" />
  <xacro:property name="astra_cam_rel_rgb_py"   value="-0.0125" />
  <xacro:property name="astra_dae_display_scale"   value="1" />

    <joint name="camera_joint" type="fixed">
      <origin xyz="${cam_px} ${astra_cam_py} ${cam_pz}" rpy="${cam_or} ${cam_op} ${cam_oy}"/>
      <parent link="base_link"/>
      <child link="camera_link" />
    </joint>

    <joint name="camera_rgb_optical_joint" type="fixed">
      <origin xyz="0 0 0" rpy="${-M_PI/2} 0 ${-M_PI/2}" />
      <parent link="camera_rgb_frame" />
      <child link="camera_rgb_optical_frame" />
    </joint>
    <link name="camera_rgb_optical_frame"/>

    <joint name="camera_rgb_joint" type="fixed">
      <origin xyz="-0.031 ${-kinect_cam_py} -0.016" rpy="0 0 0"/>
      <parent link="camera_link"/>
      <child link="camera_rgb_frame"/>
    </joint>
    <link name="camera_rgb_frame"/>
      <link name="camera_link">
      <visual>
       <origin xyz="0 0 0" rpy="0 0 ${M_PI/2}"/>
        <geometry>
         <mesh filename="package://turtlebot_description/meshes/sensors/kinect.dae"/>
        </geometry>
      </visual>
  	  <collision>
        <origin xyz="0.0 0.0 0.0" rpy="0 0 0"/>
  	    <geometry>
  	      <box size="0.07271 0.27794 0.073"/>
  	    </geometry>
  	  </collision>
      <inertial>
        <mass value="0.564" />
        <origin xyz="0 0 0" />
        <inertia ixx="0.003881243" ixy="0.0" ixz="0.0"
                 iyy="0.000498940" iyz="0.0"
                 izz="0.003879257" />
      </inertial>
    </link>

    <!-- The fixed joints & links below are usually published by static_transformers launched by the OpenNi launch
         files. However, for Gazebo simulation we need them, so we add them here.
         (Hence, don't publish them additionally!) -->
	<joint name="camera_depth_joint" type="fixed">
	  <origin xyz="0 ${2 * -kinect_cam_py} 0" rpy="0 0 0" />
	  <parent link="camera_link" />
	  <child link="camera_depth_frame" />
	</joint>
	<link name="camera_depth_frame"/>

	<joint name="camera_depth_optical_joint" type="fixed">
	  <origin xyz="0 0 0" rpy="${-M_PI/2} 0 ${-M_PI/2}" />
	  <parent link="camera_depth_frame" />
	  <child link="camera_depth_optical_frame" />
	</joint>
	<link name="camera_depth_optical_frame"/>

  <!-- Drive controller -->
<gazebo>
  <plugin name="differential_drive_controller" filename="libgazebo_ros_diff_drive.so">
    <updateRate>100.0</updateRate>
    <robotNamespace>/</robotNamespace>
    <leftJoint>base_to_wheel_left</leftJoint>
    <rightJoint>base_to_wheel_right</rightJoint>
    <wheelSeparation>4</wheelSeparation>
    <wheelDiameter>0.1</wheelDiameter>
    <robotBaseFrame>base_footprint</robotBaseFrame>
    <wheelTorque>5</wheelTorque>
    <topicName>cmd_vel</topicName>
    <commandTopic>cmd_vel</commandTopic>
    <odometryTopic>odom</odometryTopic>
    <odometryFrame>odom</odometryFrame>
    <broadcastTF>1</broadcastTF>
  </plugin>
</gazebo>


</robot>
